
Exception caught at 2021-11-06 21:33:54.032194:
Traceback (most recent call last):
  File "internal/testpy/test_framework.py", line 238, in <module>
    main()
  File "internal/testpy/test_framework.py", line 34, in main
    input("Press Enter to Exit...")
EOFError

Exception caught at 2021-11-06 21:34:23.466588:
Traceback (most recent call last):
  File "internal/testpy/test_framework.py", line 238, in <module>
    main()
  File "internal/testpy/test_framework.py", line 34, in main
    input("Press Enter to Exit...")
EOFError

Exception caught at 2021-11-06 22:04:45.153263:
Traceback (most recent call last):
  File "internal/testpy/test_framework.py", line 238, in <module>
    main()
  File "internal/testpy/test_framework.py", line 34, in main
    input("Press Enter to Exit...")
EOFError

Exception caught at 2021-11-06 22:05:41.331525:
Traceback (most recent call last):
  File "internal/testpy/test_framework.py", line 238, in <module>
    main()
  File "internal/testpy/test_framework.py", line 34, in main
    input("Press Enter to Exit...")
EOFError

Exception caught at 2021-11-06 22:45:44.073944:
Traceback (most recent call last):
  File "internal/testpy/test_framework.py", line 238, in <module>
    main()
  File "internal/testpy/test_framework.py", line 57, in main
    input("Press Enter To Exit...")
EOFError: EOF when reading a line

Exception caught at 2021-11-07 00:29:14.995504:
Traceback (most recent call last):
  File "internal/testpy/test_framework.py", line 238, in <module>
    main()
  File "internal/testpy/test_framework.py", line 57, in main
    input("Press Enter To Exit...")
EOFError: EOF when reading a line

Exception caught at 2021-11-07 01:41:03.778450:
Traceback (most recent call last):
  File "internal/testpy/test_framework.py", line 238, in <module>
    main()
  File "internal/testpy/test_framework.py", line 57, in main
    input("Press Enter To Exit...")
EOFError

Exception caught at 2021-11-07 01:41:11.557953:
Traceback (most recent call last):
  File "internal/testpy/test_framework.py", line 238, in <module>
    main()
  File "internal/testpy/test_framework.py", line 57, in main
    input("Press Enter To Exit...")
EOFError: EOF when reading a line

Exception caught at 2021-11-07 15:44:06.543819:
Traceback (most recent call last):
  File "internal/testpy/test_framework.py", line 238, in <module>
    main()
  File "internal/testpy/test_framework.py", line 57, in main
    input("Press Enter To Exit...")
EOFError

Exception caught at 2021-11-07 15:44:38.672086:
Traceback (most recent call last):
  File "internal/testpy/test_framework.py", line 238, in <module>
    main()
  File "internal/testpy/test_framework.py", line 57, in main
    input("Press Enter To Exit...")
EOFError

Exception caught at 2021-11-07 15:47:06.771945:
Traceback (most recent call last):
  File "internal/testpy/test_framework.py", line 238, in <module>
    main()
  File "internal/testpy/test_framework.py", line 57, in main
    input("Press Enter To Exit...")
EOFError

Exception caught at 2021-11-07 17:29:37.725258:
Traceback (most recent call last):
  File "internal/testpy/test_framework.py", line 238, in <module>
    main()
  File "internal/testpy/test_framework.py", line 57, in main
    input("Press Enter To Exit...")
EOFError

Exception caught at 2021-11-07 20:11:36.772314:
Traceback (most recent call last):
  File "internal/testpy/test_framework.py", line 238, in <module>
    main()
  File "internal/testpy/test_framework.py", line 57, in main
    input("Press Enter To Exit...")
EOFError: EOF when reading a line

Exception caught at 2021-12-03 17:22:19.529131:
Traceback (most recent call last):
  File "internal/testpy/test_framework.py", line 238, in <module>
    main()
  File "internal/testpy/test_framework.py", line 34, in main
    input("Press Enter to Exit...")
EOFError

Exception caught at 2021-12-03 18:31:03.531877:
Traceback (most recent call last):
  File "internal/testpy/test_framework.py", line 238, in <module>
    main()
  File "internal/testpy/test_framework.py", line 57, in main
    input("Press Enter To Exit...")
EOFError

Exception caught at 2021-12-08 14:16:19.671068:
Traceback (most recent call last):
  File "internal/testpy/test_framework.py", line 238, in <module>
    main()
  File "internal/testpy/test_framework.py", line 57, in main
    input("Press Enter To Exit...")
EOFError

Exception caught at 2021-12-08 14:16:19.672389:
Traceback (most recent call last):
  File "internal/testpy/test_framework.py", line 238, in <module>
    main()
  File "internal/testpy/test_framework.py", line 57, in main
    input("Press Enter To Exit...")
EOFError

Exception caught at 2021-12-08 14:16:19.671271:
Traceback (most recent call last):
  File "internal/testpy/test_framework.py", line 238, in <module>
    main()
  File "internal/testpy/test_framework.py", line 57, in main
    input("Press Enter To Exit...")
EOFError

Exception caught at 2021-12-08 14:16:19.671560:
Traceback (most recent call last):
  File "internal/testpy/test_framework.py", line 238, in <module>
    main()
  File "internal/testpy/test_framework.py", line 57, in main
    input("Press Enter To Exit...")
EOFError

Exception caught at 2021-12-08 14:16:19.673588:
Traceback (most recent call last):
  File "internal/testpy/test_framework.py", line 238, in <module>
    main()
  File "internal/testpy/test_framework.py", line 57, in main
    input("Press Enter To Exit...")
EOFError

Exception caught at 2021-12-08 14:16:21.691857:
Traceback (most recent call last):
  File "internal/testpy/test_framework.py", line 238, in <module>
    main()
  File "internal/testpy/test_framework.py", line 57, in main
    input("Press Enter To Exit...")
EOFError: EOF when reading a line

Exception caught at 2021-12-09 21:18:42.592892:
Traceback (most recent call last):
  File "internal/testpy/test_framework.py", line 238, in <module>
    main()
  File "internal/testpy/test_framework.py", line 57, in main
    input("Press Enter To Exit...")
EOFError: EOF when reading a line

Exception caught at 2021-12-09 23:19:43.651109:
Traceback (most recent call last):
  File "internal/testpy/test_framework.py", line 238, in <module>
    main()
  File "internal/testpy/test_framework.py", line 57, in main
    input("Press Enter To Exit...")
EOFError: EOF when reading a line

Exception caught at 2021-12-10 13:16:33.586080:
Traceback (most recent call last):
  File "internal/testpy/test_framework.py", line 238, in <module>
    main()
  File "internal/testpy/test_framework.py", line 57, in main
    input("Press Enter To Exit...")
EOFError

Exception caught at 2021-12-10 22:57:24.238194:
Traceback (most recent call last):
  File "internal/testpy/test_framework.py", line 238, in <module>
    main()
  File "internal/testpy/test_framework.py", line 57, in main
    input("Press Enter To Exit...")
EOFError

Exception caught at 2021-12-10 22:57:24.238480:
Traceback (most recent call last):
  File "internal/testpy/test_framework.py", line 238, in <module>
    main()
  File "internal/testpy/test_framework.py", line 57, in main
    input("Press Enter To Exit...")
EOFError

Exception caught at 2021-12-10 22:57:24.238854:
Traceback (most recent call last):
  File "internal/testpy/test_framework.py", line 238, in <module>
    main()
  File "internal/testpy/test_framework.py", line 57, in main
    input("Press Enter To Exit...")
EOFError

Exception caught at 2021-12-10 22:57:24.251018:
Traceback (most recent call last):
  File "internal/testpy/test_framework.py", line 238, in <module>
    main()
  File "internal/testpy/test_framework.py", line 57, in main
    input("Press Enter To Exit...")
EOFError

Exception caught at 2021-12-10 22:57:24.239081:
Traceback (most recent call last):
  File "/usr/lib64/python3.6/tkinter/__init__.py", line 1705, in __call__
    return self.func(*args)
  File "/home/sfstowe/sfstowe/cpre381/ProjPart2/sPipelinedProcessor/test_sw/Framework/internal/testpy/run_gui.py", line 197, in chooseSelectedFiles
    test_framework.queueSimulation(asm_files_to_run, options)
  File "/home/sfstowe/sfstowe/cpre381/ProjPart2/sPipelinedProcessor/test_sw/Framework/internal/testpy/test_framework.py", line 65, in queueSimulation
    runSimulation(x,simOptions)
  File "/home/sfstowe/sfstowe/cpre381/ProjPart2/sPipelinedProcessor/test_sw/Framework/internal/testpy/test_framework.py", line 72, in runSimulation
    options['asm-path'] = mars.run_sim(asm_file=asm_Path)
  File "/home/sfstowe/sfstowe/cpre381/ProjPart2/sPipelinedProcessor/test_sw/Framework/internal/testpy/mars.py", line 72, in run_sim
    return run_sim()
  File "/home/sfstowe/sfstowe/cpre381/ProjPart2/sPipelinedProcessor/test_sw/Framework/internal/testpy/mars.py", line 45, in run_sim
    path = input('>').strip()
EOFError

During handling of the above exception, another exception occurred:

Traceback (most recent call last):
  File "internal/testpy/test_framework.py", line 238, in <module>
    main()
  File "internal/testpy/test_framework.py", line 55, in main
    run_gui.guiMain()
  File "/home/sfstowe/sfstowe/cpre381/ProjPart2/sPipelinedProcessor/test_sw/Framework/internal/testpy/run_gui.py", line 156, in guiMain
    window.mainloop()
  File "/usr/lib64/python3.6/tkinter/__init__.py", line 1283, in mainloop
    self.tk.mainloop(n)
  File "/usr/lib64/python3.6/tkinter/__init__.py", line 1709, in __call__
    self.widget._report_exception()
  File "/usr/lib64/python3.6/tkinter/__init__.py", line 1452, in _report_exception
    root.report_callback_exception(exc, val, tb)
  File "/usr/lib64/python3.6/tkinter/__init__.py", line 2094, in report_callback_exception
    print("Exception in Tkinter callback", file=sys.stderr)
OSError: [Errno 5] Input/output error

Exception caught at 2021-12-10 23:36:53.891594:
Traceback (most recent call last):
  File "/usr/lib64/python3.6/tkinter/__init__.py", line 1705, in __call__
    return self.func(*args)
  File "/home/bmoeckly/cpre381/project2/sPipelinedProcessor/test_sw/Framework/internal/testpy/run_gui.py", line 197, in chooseSelectedFiles
    test_framework.queueSimulation(asm_files_to_run, options)
  File "/home/bmoeckly/cpre381/project2/sPipelinedProcessor/test_sw/Framework/internal/testpy/test_framework.py", line 65, in queueSimulation
    runSimulation(x,simOptions)
  File "/home/bmoeckly/cpre381/project2/sPipelinedProcessor/test_sw/Framework/internal/testpy/test_framework.py", line 72, in runSimulation
    options['asm-path'] = mars.run_sim(asm_file=asm_Path)
  File "/home/bmoeckly/cpre381/project2/sPipelinedProcessor/test_sw/Framework/internal/testpy/mars.py", line 72, in run_sim
    return run_sim()
  File "/home/bmoeckly/cpre381/project2/sPipelinedProcessor/test_sw/Framework/internal/testpy/mars.py", line 45, in run_sim
    path = input('>').strip()
EOFError

During handling of the above exception, another exception occurred:

Traceback (most recent call last):
  File "internal/testpy/test_framework.py", line 238, in <module>
    main()
  File "internal/testpy/test_framework.py", line 55, in main
    run_gui.guiMain()
  File "/home/bmoeckly/cpre381/project2/sPipelinedProcessor/test_sw/Framework/internal/testpy/run_gui.py", line 156, in guiMain
    window.mainloop()
  File "/usr/lib64/python3.6/tkinter/__init__.py", line 1283, in mainloop
    self.tk.mainloop(n)
  File "/usr/lib64/python3.6/tkinter/__init__.py", line 1709, in __call__
    self.widget._report_exception()
  File "/usr/lib64/python3.6/tkinter/__init__.py", line 1452, in _report_exception
    root.report_callback_exception(exc, val, tb)
  File "/usr/lib64/python3.6/tkinter/__init__.py", line 2094, in report_callback_exception
    print("Exception in Tkinter callback", file=sys.stderr)
OSError: [Errno 5] Input/output error

Exception caught at 2021-12-10 23:39:20.793942:
Traceback (most recent call last):
  File "internal/testpy/test_framework.py", line 238, in <module>
    main()
  File "internal/testpy/test_framework.py", line 57, in main
    input("Press Enter To Exit...")
EOFError: EOF when reading a line
